Workbook

Sheet Claude Cache
A1: ⚠️ SHEET RESERVED FOR =CLAUDE... FUNCTIONS. DO NOT EDIT! ⚠️
A2: Key | B2: Value | C2: Expiration

Sheet Overall
A1: ='Dropdown Lists'!E3 -> UPI/Bank Accounts | B1: Starting Balance | C1: Direct Spend | D1: CC Bill Paid | E1: Net Transfer | F1: Current Balance | I1: Salary Date | J1: Salary Month | K1: Amount
A2: ='Dropdown Lists'!E2 -> Cash Payment | B2: 2080 | C2: =IFERROR(SUMIFS(Kharche!$H:$H, Kharche!$E:$E, $A2, Kharche!$E:$E, "<>Credit Card"), 0) -> 1000 | D2: =IFERROR(SUMIF('Credit Card Bills'!$B:$B, $A2, 'Credit Card Bills'!$D:$D), 0) -> 0 | E2: =IFERROR(SUMIF('AdhocSelf Transfer'!$C:$C, $A2, 'AdhocSelf Transfer'!$D:$D), 0) - IFERROR(SUMIF('AdhocSelf Transfer'!$B:$B, $A2, 'AdhocSelf Transfer'!$D:$D), 0) -> 7500 | F2: =$B2 - $C2 - $D2 + $E2 -> 8580 | I2: =DATE(2026,2,27) -> 46080 | J2: 46054 | K2: 111559
A3: ='Dropdown Lists'!F3 -> Axis Bank | B3: =564507.85+sum(K2:K16) -> 676066.85 | C3: =IFERROR(SUMIFS(Kharche!$H:$H, Kharche!$F:$F, $A3, Kharche!$E:$E, $A$1, Kharche!$E:$E, "<>Credit Card"), 0) -> 133608 | D3: =IFERROR(SUMIF('Credit Card Bills'!$B:$B, $A3, 'Credit Card Bills'!$D:$D), 0) -> 2371.5 | E3: =IFERROR(SUMIF('AdhocSelf Transfer'!$C:$C, $A3, 'AdhocSelf Transfer'!$D:$D), 0) - IFERROR(SUMIF('AdhocSelf Transfer'!$B:$B, $A3, 'AdhocSelf Transfer'!$D:$D), 0) -> -84718.73 | F3: =$B3 - $C3 - $D3 + $E3 -> 455368.62
A4: ='Dropdown Lists'!F4 -> State Bank of India (SBI) | B4: 11835 | C4: =IFERROR(SUMIFS(Kharche!$H:$H, Kharche!$F:$F, $A4, Kharche!$E:$E, $A$1, Kharche!$E:$E, "<>Credit Card"), 0) -> 63102.88 | D4: =IFERROR(SUMIF('Credit Card Bills'!$B:$B, $A4, 'Credit Card Bills'!$D:$D), 0) -> 0 | E4: =IFERROR(SUMIF('AdhocSelf Transfer'!$C:$C, $A4, 'AdhocSelf Transfer'!$D:$D), 0) - IFERROR(SUMIF('AdhocSelf Transfer'!$B:$B, $A4, 'AdhocSelf Transfer'!$D:$D), 0) -> 59319.47 | F4: =$B4 - $C4 - $D4 + $E4 -> 8051.59
A5: ='Dropdown Lists'!F5 -> Amazon Pay | B5: 271.66 | C5: =IFERROR(SUMIFS(Kharche!$H:$H, Kharche!$F:$F, $A5, Kharche!$E:$E, $A$1, Kharche!$E:$E, "<>Credit Card"), 0) -> 2200 | D5: =IFERROR(SUMIF('Credit Card Bills'!$B:$B, $A5, 'Credit Card Bills'!$D:$D), 0) -> 0 | E5: =IFERROR(SUMIF('AdhocSelf Transfer'!$C:$C, $A5, 'AdhocSelf Transfer'!$D:$D), 0) - (IFERROR(SUMIF('AdhocSelf Transfer'!$B:$B, $A5, 'AdhocSelf Transfer'!$D:$D), 0)+IFERROR(SUMIF('AdhocSelf Transfer'!$B:$B, $A5, 'AdhocSelf Transfer'!$E:$E), 0)) -> 1928.34 | F5: =$B5 - $C5 - $D5 + $E5 -> 0
A6: ='Dropdown Lists'!F6 -> Groww Account | B6: 0 | C6: =IFERROR(SUMIFS(Kharche!$H:$H, Kharche!$F:$F, $A6, Kharche!$E:$E, $A$1, Kharche!$E:$E, "<>Credit Card"), 0) -> 105119.12 | D6: =IFERROR(SUMIF('Credit Card Bills'!$B:$B, $A6, 'Credit Card Bills'!$D:$D), 0) -> 0 | E6: =IFERROR(SUMIF('AdhocSelf Transfer'!$C:$C, $A6, 'AdhocSelf Transfer'!$D:$D), 0) - (IFERROR(SUMIF('AdhocSelf Transfer'!$B:$B, $A6, 'AdhocSelf Transfer'!$D:$D), 0)+IFERROR(SUMIF('AdhocSelf Transfer'!$B:$B, $A6, 'AdhocSelf Transfer'!$E:$E), 0)) -> 113722.4 | F6: =$B6 - $C6 - $D6 + $E6 -> 8603.28
A7: ='Dropdown Lists'!E10 -> Splitwise | B7: 116146.39 | C7: =IFERROR(SUMIFS(Kharche!$H:$H, Kharche!$E:$E, $A7, Kharche!$E:$E, "<>Credit Card"), 0) -> 1155 | D7: =IFERROR(SUMIF('Credit Card Bills'!$B:$B, $A7, 'Credit Card Bills'!$D:$D), 0) -> 0 | E7: =IFERROR(SUMIF('AdhocSelf Transfer'!$C:$C, $A7, 'AdhocSelf Transfer'!$D:$D), 0) - (IFERROR(SUMIF('AdhocSelf Transfer'!$B:$B, $A7, 'AdhocSelf Transfer'!$D:$D), 0)+IFERROR(SUMIF('AdhocSelf Transfer'!$B:$B, $A7, 'AdhocSelf Transfer'!$E:$E), 0)) -> -78014.75 | F7: =$B7 - $C7 - $D7 + $E7 -> 36976.64
A8: Investments | B8: 348935 | C8: =-IFERROR(SUMIFS(Kharche!$H:$H, Kharche!$C:$C, $A8, Kharche!$E:$E, "<>Credit Card"), 0) -> -234297.12 | D8: =IFERROR(SUMIF('Credit Card Bills'!$B:$B, $A8, 'Credit Card Bills'!$D:$D), 0) -> 0 | E8: =IFERROR(SUMIF('AdhocSelf Transfer'!$C:$C, $A8, 'AdhocSelf Transfer'!$D:$D), 0) - (IFERROR(SUMIF('AdhocSelf Transfer'!$B:$B, $A8, 'AdhocSelf Transfer'!$D:$D), 0)+IFERROR(SUMIF('AdhocSelf Transfer'!$B:$B, $A8, 'AdhocSelf Transfer'!$E:$E), 0)) -> 0 | F8: =$B8 - $C8 - $D8 + $E8 -> 583232.12
E9: Net Worth | F9: =Sum(F3:F8) -> 1092232.2
E10: Cash in Bank | F10: =sum(F3:F4) -> 463420.21
A14: Total CC Spends
A15: ='Dropdown Lists'!E7 -> Credit Card | B15: Total Spend | C15: Cashback | D15: Total Paid | E15: Outstanding
A16: ='Dropdown Lists'!F7 -> Axis Bank CC | B16: =IFERROR(SUMIFS(Kharche!$H:$H, Kharche!$E:$E, "Credit Card", Kharche!$F:$F, $A16), 0) -> 4432 | C16: =IFERROR(SUMIF('AdhocSelf Transfer'!$C:$C, $A16, 'AdhocSelf Transfer'!$D:$D), 0) -(IFERROR(SUMIF('AdhocSelf Transfer'!$B:$B, $A16, 'AdhocSelf Transfer'!$D:$D), 0)+IFERROR(SUMIF('AdhocSelf Transfer'!$B:$B, $A16, 'AdhocSelf Transfer'!$E:$E), 0)) -> 254 | D16: =IFERROR(SUMIF('Credit Card Bills'!$C:$C, $A16, 'Credit Card Bills'!$D:$D), 0) -> 2371.5 | E16: =$B16 - $D16-C16 -> 1806.5
A17: ='Dropdown Lists'!F8 -> ICICI | B17: =IFERROR(SUMIFS(Kharche!$H:$H, Kharche!$E:$E, "Credit Card", Kharche!$F:$F, $A17), 0) -> 0 | C17: =IFERROR(SUMIF('AdhocSelf Transfer'!$C:$C, $A17, 'AdhocSelf Transfer'!$D:$D), 0) -(IFERROR(SUMIF('AdhocSelf Transfer'!$B:$B, $A17, 'AdhocSelf Transfer'!$D:$D), 0)+IFERROR(SUMIF('AdhocSelf Transfer'!$B:$B, $A17, 'AdhocSelf Transfer'!$E:$E), 0)) -> 0 | D17: =IFERROR(SUMIF('Credit Card Bills'!$C:$C, $A17, 'Credit Card Bills'!$D:$D), 0) -> 0 | E17: =$B17 - $D17-C17 -> 0
A18: ='Dropdown Lists'!F9 -> Scapia | B18: =IFERROR(SUMIFS(Kharche!$H:$H, Kharche!$E:$E, "Credit Card", Kharche!$F:$F, $A18), 0) -> 8307 | C18: =IFERROR(SUMIF('AdhocSelf Transfer'!$C:$C, $A18, 'AdhocSelf Transfer'!$D:$D), 0) -(IFERROR(SUMIF('AdhocSelf Transfer'!$B:$B, $A18, 'AdhocSelf Transfer'!$D:$D), 0)+IFERROR(SUMIF('AdhocSelf Transfer'!$B:$B, $A18, 'AdhocSelf Transfer'!$E:$E), 0)) -> 0 | D18: =IFERROR(SUMIF('Credit Card Bills'!$C:$C, $A18, 'Credit Card Bills'!$D:$D), 0) -> 0 | E18: =$B18 - $D18-C18 -> 8307
A19: Monthly Analytics
A20: Month | B20: Income | C20: Total Expense | D20: =concat('Dropdown Lists'!$F$3," Spends") -> Axis Bank Spends | E20: =concat('Dropdown Lists'!$F$4," Spends") -> State Bank of India (SBI) Spends | F20: =concat('Dropdown Lists'!$F$5," Spends") -> Amazon Pay Spends | G20: =concat('Dropdown Lists'!$F$6," Spends") -> Groww Account Spends | H20: =concat('Dropdown Lists'!$E$10," Spends") -> Splitwise Spends | I20: Other Spends | J20: =concat('Dropdown Lists'!$F$7," Spends") -> Axis Bank CC Spends | K20: =concat('Dropdown Lists'!$F$8," Spends") -> ICICI Spends | L20: =concat('Dropdown Lists'!$F$9," Spends") -> Scapia Spends | M20: Total CC Spends | N20: CC Bills Paid (Total) | O20: Monthly Investments | P20: =concat('Dropdown Lists'!$F$3," Net Self Transfer") -> Axis Bank Net Self Transfer | Q20: =concat('Dropdown Lists'!$F$4," Net Self Transfer") -> State Bank of India (SBI) Net Self Transfer | R20: =concat('Dropdown Lists'!$F$5," Net Self Transfer") -> Amazon Pay Net Self Transfer | S20: =concat('Dropdown Lists'!$F$6," Net Self Transfer") -> Groww Account Net Self Transfer | T20: =concat('Dropdown Lists'!$E$10," Net Self Transfer") -> Splitwise Net Self Transfer
A21: 46054 | B21: =IFERROR(SUMIFS($K:$K, $J:$J, ">="&$A21, $J:$J, "<="&EOMONTH($A21,0)), 0) -> 111559 | C21: =IFERROR(SUMIFS(Kharche!$H:$H, Kharche!$A:$A, ">="&$A21, Kharche!$A:$A, "<="&EOMONTH($A21,0)), 0) -> 15018.83 | D21: =IFERROR(SUMIFS(Kharche!$H:$H, Kharche!$A:$A, ">="&$A21, Kharche!$A:$A, "<="&EOMONTH($A21,0), Kharche!$E:$E, 'Dropdown Lists'!$E$3, Kharche!$F:$F, 'Dropdown Lists'!$F$3), 0) -> 0 | E21: =IFERROR(SUMIFS(Kharche!$H:$H, Kharche!$A:$A, ">="&$A21, Kharche!$A:$A, "<="&EOMONTH($A21,0), Kharche!$E:$E, 'Dropdown Lists'!$E$3, Kharche!$F:$F, 'Dropdown Lists'!$F$4), 0) -> 11438.83 | F21: =IFERROR(SUMIFS(Kharche!$H:$H, Kharche!$A:$A, ">="&$A21, Kharche!$A:$A, "<="&EOMONTH($A21,0), Kharche!$E:$E, 'Dropdown Lists'!$E$3, Kharche!$F:$F, 'Dropdown Lists'!$F$5), 0) -> 0 | G21: =IFERROR(SUMIFS(Kharche!$H:$H, Kharche!$A:$A, ">="&$A21, Kharche!$A:$A, "<="&EOMONTH($A21,0), Kharche!$E:$E, 'Dropdown Lists'!$E$3, Kharche!$F:$F, 'Dropdown Lists'!$F$6), 0) -> 0 | H21: =IFERROR(SUMIFS(Kharche!$H:$H, Kharche!$A:$A, ">="&$A21, Kharche!$A:$A, "<="&EOMONTH($A21,0), Kharche!$E:$E, 'Dropdown Lists'!$E$10), 0) -> 0 | I21: =sum(F21:H21) -> 0 | J21: =IFERROR(SUMIFS(Kharche!$H:$H, Kharche!$A:$A, ">="&$A21, Kharche!$A:$A, "<="&EOMONTH($A21,0), Kharche!$E:$E, 'Dropdown Lists'!$E$7, Kharche!$F:$F, 'Dropdown Lists'!$F$7), 0) -> 1581 | K21: =IFERROR(SUMIFS(Kharche!$H:$H, Kharche!$A:$A, ">="&$A21, Kharche!$A:$A, "<="&EOMONTH($A21,0), Kharche!$E:$E, 'Dropdown Lists'!$E$8, Kharche!$F:$F, 'Dropdown Lists'!$F$8), 0) -> 0 | L21: =IFERROR(SUMIFS(Kharche!$H:$H, Kharche!$A:$A, ">="&$A21, Kharche!$A:$A, "<="&EOMONTH($A21,0), Kharche!$E:$E, 'Dropdown Lists'!$E$9, Kharche!$F:$F, 'Dropdown Lists'!$F$9), 0) -> 1999 | M21: =sum(J21:L21) -> 3580 | N21: =IFERROR(SUMIFS('Credit Card Bills'!$D:$D, 'Credit Card Bills'!$A:$A, ">="&$A21, 'Credit Card Bills'!$A:$A, "<="&EOMONTH($A21,0)), 0) -> 0 | O21: =IFERROR(SUMIFS(Kharche!$H:$H, Kharche!$A:$A, ">="&$A21, Kharche!$A:$A, "<="&EOMONTH($A21,0), Kharche!$C:$C, 'Dropdown Lists'!$B$29), 0) -> 0 | P21: =IFERROR(SUMIFS('AdhocSelf Transfer'!$D:$D, 'AdhocSelf Transfer'!$A:$A, ">="&$A21, 'AdhocSelf Transfer'!$A:$A, "<="&EOMONTH($A21,0), 'AdhocSelf Transfer'!$C:$C, 'Dropdown Lists'!$F$3), 0) - IFERROR(SUMIFS('AdhocSelf Transfer'!$D:$D, 'AdhocSelf Transfer'!$A:$A, ">="&$A21, 'AdhocSelf Transfer'!$A:$A, "<="&EOMONTH($A21,0), 'AdhocSelf Transfer'!$B:$B, 'Dropdown Lists'!$F$3), 0) -> 41.25 | Q21: =IFERROR(SUMIFS('AdhocSelf Transfer'!$D:$D, 'AdhocSelf Transfer'!$A:$A, ">="&$A21, 'AdhocSelf Transfer'!$A:$A, "<="&EOMONTH($A21,0), 'AdhocSelf Transfer'!$C:$C, 'Dropdown Lists'!$F$4), 0) - IFERROR(SUMIFS('AdhocSelf Transfer'!$D:$D, 'AdhocSelf Transfer'!$A:$A, ">="&$A21, 'AdhocSelf Transfer'!$A:$A, "<="&EOMONTH($A21,0), 'AdhocSelf Transfer'!$B:$B, 'Dropdown Lists'!$F$4), 0) -> 0 | R21: =IFERROR(SUMIFS('AdhocSelf Transfer'!$D:$D, 'AdhocSelf Transfer'!$A:$A, ">="&$A21, 'AdhocSelf Transfer'!$A:$A, "<="&EOMONTH($A21,0), 'AdhocSelf Transfer'!$C:$C, 'Dropdown Lists'!$F$5), 0) - IFERROR(SUMIFS('AdhocSelf Transfer'!$D:$D, 'AdhocSelf Transfer'!$A:$A, ">="&$A21, 'AdhocSelf Transfer'!$A:$A, "<="&EOMONTH($A21,0), 'AdhocSelf Transfer'!$B:$B, 'Dropdown Lists'!$F$5), 0) -> 0 | S21: =IFERROR(SUMIFS('AdhocSelf Transfer'!$D:$D, 'AdhocSelf Transfer'!$A:$A, ">="&$A21, 'AdhocSelf Transfer'!$A:$A, "<="&EOMONTH($A21,0), 'AdhocSelf Transfer'!$C:$C, 'Dropdown Lists'!$F$6), 0) - IFERROR(SUMIFS('AdhocSelf Transfer'!$D:$D, 'AdhocSelf Transfer'!$A:$A, ">="&$A21, 'AdhocSelf Transfer'!$A:$A, "<="&EOMONTH($A21,0), 'AdhocSelf Transfer'!$B:$B, 'Dropdown Lists'!$F$6), 0) -> 0 | T21: =IFERROR(SUMIFS('AdhocSelf Transfer'!$D:$D, 'AdhocSelf Transfer'!$A:$A, ">="&$A21, 'AdhocSelf Transfer'!$A:$A, "<="&EOMONTH($A21,0), 'AdhocSelf Transfer'!$C:$C, 'Dropdown Lists'!$E$10), 0) - IFERROR(SUMIFS('AdhocSelf Transfer'!$D:$D, 'AdhocSelf Transfer'!$A:$A, ">="&$A21, 'AdhocSelf Transfer'!$A:$A, "<="&EOMONTH($A21,0), 'AdhocSelf Transfer'!$B:$B, 'Dropdown Lists'!$E$10), 0) -> 0
A22: 46082 | B22: =IFERROR(SUMIFS($K:$K, $J:$J, ">="&$A22, $J:$J, "<="&EOMONTH($A22,0)), 0) -> 0 | C22: =IFERROR(SUMIFS(Kharche!$H:$H, Kharche!$A:$A, ">="&$A22, Kharche!$A:$A, "<="&EOMONTH($A22,0)), 0) -> 303905.17 | D22: =IFERROR(SUMIFS(Kharche!$H:$H, Kharche!$A:$A, ">="&$A22, Kharche!$A:$A, "<="&EOMONTH($A22,0), Kharche!$E:$E, 'Dropdown Lists'!$E$3, Kharche!$F:$F, 'Dropdown Lists'!$F$3), 0) -> 133608 | E22: =IFERROR(SUMIFS(Kharche!$H:$H, Kharche!$A:$A, ">="&$A22, Kharche!$A:$A, "<="&EOMONTH($A22,0), Kharche!$E:$E, 'Dropdown Lists'!$E$3, Kharche!$F:$F, 'Dropdown Lists'!$F$4), 0) -> 51664.05 | F22: =IFERROR(SUMIFS(Kharche!$H:$H, Kharche!$A:$A, ">="&$A22, Kharche!$A:$A, "<="&EOMONTH($A22,0), Kharche!$E:$E, 'Dropdown Lists'!$E$3, Kharche!$F:$F, 'Dropdown Lists'!$F$5), 0) -> 2200 | G22: =IFERROR(SUMIFS(Kharche!$H:$H, Kharche!$A:$A, ">="&$A22, Kharche!$A:$A, "<="&EOMONTH($A22,0), Kharche!$E:$E, 'Dropdown Lists'!$E$3, Kharche!$F:$F, 'Dropdown Lists'!$F$6), 0) -> 105119.12 | H22: =IFERROR(SUMIFS(Kharche!$H:$H, Kharche!$A:$A, ">="&$A22, Kharche!$A:$A, "<="&EOMONTH($A22,0), Kharche!$E:$E, 'Dropdown Lists'!$E$10), 0) -> 1155 | I22: =sum(F22:H22) -> 108474.12 | J22: =IFERROR(SUMIFS(Kharche!$H:$H, Kharche!$A:$A, ">="&$A22, Kharche!$A:$A, "<="&EOMONTH($A22,0), Kharche!$E:$E, 'Dropdown Lists'!$E$7, Kharche!$F:$F, 'Dropdown Lists'!$F$7), 0) -> 2851 | K22: =IFERROR(SUMIFS(Kharche!$H:$H, Kharche!$A:$A, ">="&$A22, Kharche!$A:$A, "<="&EOMONTH($A22,0), Kharche!$E:$E, 'Dropdown Lists'!$E$8, Kharche!$F:$F, 'Dropdown Lists'!$F$8), 0) -> 0 | L22: =IFERROR(SUMIFS(Kharche!$H:$H, Kharche!$A:$A, ">="&$A22, Kharche!$A:$A, "<="&EOMONTH($A22,0), Kharche!$E:$E, 'Dropdown Lists'!$E$9, Kharche!$F:$F, 'Dropdown Lists'!$F$9), 0) -> 6308 | M22: =sum(J22:L22) -> 9159 | N22: =IFERROR(SUMIFS('Credit Card Bills'!$D:$D, 'Credit Card Bills'!$A:$A, ">="&$A22, 'Credit Card Bills'!$A:$A, "<="&EOMONTH($A22,0)), 0) -> 2371.5 | O22: =IFERROR(SUMIFS(Kharche!$H:$H, Kharche!$A:$A, ">="&$A22, Kharche!$A:$A, "<="&EOMONTH($A22,0), Kharche!$C:$C, 'Dropdown Lists'!$B$29), 0) -> 234297.12 | P22: =IFERROR(SUMIFS('AdhocSelf Transfer'!$D:$D, 'AdhocSelf Transfer'!$A:$A, ">="&$A22, 'AdhocSelf Transfer'!$A:$A, "<="&EOMONTH($A22,0), 'AdhocSelf Transfer'!$C:$C, 'Dropdown Lists'!$F$3), 0) - IFERROR(SUMIFS('AdhocSelf Transfer'!$D:$D, 'AdhocSelf Transfer'!$A:$A, ">="&$A22, 'AdhocSelf Transfer'!$A:$A, "<="&EOMONTH($A22,0), 'AdhocSelf Transfer'!$B:$B, 'Dropdown Lists'!$F$3), 0) -> -134759.98 | Q22: =IFERROR(SUMIFS('AdhocSelf Transfer'!$D:$D, 'AdhocSelf Transfer'!$A:$A, ">="&$A22, 'AdhocSelf Transfer'!$A:$A, "<="&EOMONTH($A22,0), 'AdhocSelf Transfer'!$C:$C, 'Dropdown Lists'!$F$4), 0) - IFERROR(SUMIFS('AdhocSelf Transfer'!$D:$D, 'AdhocSelf Transfer'!$A:$A, ">="&$A22, 'AdhocSelf Transfer'!$A:$A, "<="&EOMONTH($A22,0), 'AdhocSelf Transfer'!$B:$B, 'Dropdown Lists'!$F$4), 0) -> 31305.47 | R22: =IFERROR(SUMIFS('AdhocSelf Transfer'!$D:$D, 'AdhocSelf Transfer'!$A:$A, ">="&$A22, 'AdhocSelf Transfer'!$A:$A, "<="&EOMONTH($A22,0), 'AdhocSelf Transfer'!$C:$C, 'Dropdown Lists'!$F$5), 0) - IFERROR(SUMIFS('AdhocSelf Transfer'!$D:$D, 'AdhocSelf Transfer'!$A:$A, ">="&$A22, 'AdhocSelf Transfer'!$A:$A, "<="&EOMONTH($A22,0), 'AdhocSelf Transfer'!$B:$B, 'Dropdown Lists'!$F$5), 0) -> 1928.34 | S22: =IFERROR(SUMIFS('AdhocSelf Transfer'!$D:$D, 'AdhocSelf Transfer'!$A:$A, ">="&$A22, 'AdhocSelf Transfer'!$A:$A, "<="&EOMONTH($A22,0), 'AdhocSelf Transfer'!$C:$C, 'Dropdown Lists'!$F$6), 0) - IFERROR(SUMIFS('AdhocSelf Transfer'!$D:$D, 'AdhocSelf Transfer'!$A:$A, ">="&$A22, 'AdhocSelf Transfer'!$A:$A, "<="&EOMONTH($A22,0), 'AdhocSelf Transfer'!$B:$B, 'Dropdown Lists'!$F$6), 0) -> 113722.4 | T22: =IFERROR(SUMIFS('AdhocSelf Transfer'!$D:$D, 'AdhocSelf Transfer'!$A:$A, ">="&$A22, 'AdhocSelf Transfer'!$A:$A, "<="&EOMONTH($A22,0), 'AdhocSelf Transfer'!$C:$C, 'Dropdown Lists'!$E$10), 0) - IFERROR(SUMIFS('AdhocSelf Transfer'!$D:$D, 'AdhocSelf Transfer'!$A:$A, ">="&$A22, 'AdhocSelf Transfer'!$A:$A, "<="&EOMONTH($A22,0), 'AdhocSelf Transfer'!$B:$B, 'Dropdown Lists'!$E$10), 0) -> 0

Sheet Kharche
A1: Day to Day Expenses
A2: Date | B2: Particulars | C2: Category | D2: Subcategory | E2: Account | F2: Account - Subcategory | G2: Application | H2: Amount | M2: Monthly Fixed Budget | N2: =TEXT(DATE(2026,2,17),"MMM YYYY") -> Feb 2026 | O2: =TEXT(DATE(2026,3,1),"MMM YYYY") -> Mar 2026
A3: =DATE(2026,2,17) -> 46070 | B3: Chat-GPT Subscription | C3: Subscriptions | E3: Credit Card | F3: Scapia | G3: Scapia | H3: 1999 | K3: Fixed Spends | L3: Maid Salary | M3: 5000 | N3: =IFERROR(__xludf.DUMMYFUNCTION("IFERROR(SUM(FILTER($H:$H, $D:$D=$L3, TEXT($A:$A,""MMM YYYY"")=N$2)),0)"),0.0) -> 0 | O3: =IFERROR(__xludf.DUMMYFUNCTION("IFERROR(SUM(FILTER($H:$H, $D:$D=$L3, TEXT($A:$A,""MMM YYYY"")=O$2)),0)"),5000.0) -> 5000
A4: =DATE(2026,2,18) -> 46071 | B4: Blinkit | C4: Household | D4: Fixed Groceries | E4: UPI/Bank Accounts | F4: State Bank of India (SBI) | G4: Paytm | H4: 228.69 | L4: Rent | M4: 11500 | N4: =IFERROR(__xludf.DUMMYFUNCTION("IFERROR(SUM(FILTER($H:$H, $D:$D=$L4, TEXT($A:$A,""MMM YYYY"")=$N$2)),0)"),0.0) -> 0 | O4: =IFERROR(__xludf.DUMMYFUNCTION("IFERROR(SUM(FILTER($H:$H, 'AdhocSelf Transfer'!$C:$C=""Axis Bank"", TEXT('AdhocSelf Transfer'!$A:$A,""MMM YYYY"")=A$25)),0)"),0.0) -> 0
A5: =DATE(2026,2,18) -> 46071 | B5: Electricity Bill | C5: Household | D5: Electricity | E5: UPI/Bank Accounts | F5: State Bank of India (SBI) | G5: Paytm | H5: 890 | L5: Furniture Rent | M5: 6304 | N5: =IFERROR(__xludf.DUMMYFUNCTION("IFERROR(SUM(FILTER($H:$H, $D:$D=$L5, TEXT($A:$A,""MMM YYYY"")=$N$2)),0)"),0.0) -> 0 | O5: =IFERROR(__xludf.DUMMYFUNCTION("IFERROR(SUM(FILTER($H:$H, $D:$D=$L5, TEXT($A:$A,""MMM YYYY"")=O$2)),0)"),6308.0) -> 6308
A6: =DATE(2026,2,18) -> 46071 | B6: Pani Puri | C6: Food and Drinks | D6: Eating Out | E6: UPI/Bank Accounts | F6: State Bank of India (SBI) | G6: Paytm | H6: 40 | L6: Fixed Groceries | M6: 3000 | N6: =IFERROR(__xludf.DUMMYFUNCTION("IFERROR(SUM(FILTER($H:$H, $D:$D=$L6, TEXT($A:$A,""MMM YYYY"")=$N$2)),0)"),561.19) -> 561.19 | O6: =IFERROR(__xludf.DUMMYFUNCTION("IFERROR(SUM(FILTER($H:$H, $D:$D=$L6, TEXT($A:$A,""MMM YYYY"")=O$2)),0)"),1733.0) -> 1733
A7: =DATE(2026,2,21) -> 46074 | B7: Blinkit | C7: Household | D7: Random Groceries | E7: UPI/Bank Accounts | F7: State Bank of India (SBI) | G7: Paytm | H7: 626.28 | L7: Electricity | M7: 1200 | N7: =IFERROR(__xludf.DUMMYFUNCTION("IFERROR(SUM(FILTER($H:$H, $D:$D=$L7, TEXT($A:$A,""MMM YYYY"")=$N$2)),0)"),890.0) -> 890 | O7: =IFERROR(__xludf.DUMMYFUNCTION("IFERROR(SUM(FILTER($H:$H, $D:$D=$L7, TEXT($A:$A,""MMM YYYY"")=O$2)),0)"),0.0) -> 0
A8: =DATE(2026,2,21) -> 46074 | B8: Beers Revant | C8: Cigarettes | E8: UPI/Bank Accounts | F8: State Bank of India (SBI) | G8: Paytm | H8: 1240 | L8: Gas Bill | M8: 350 | N8: =IFERROR(__xludf.DUMMYFUNCTION("IFERROR(SUM(FILTER($H:$H, $D:$D=$L8, TEXT($A:$A,""MMM YYYY"")=$N$2)),0)"),0.0) -> 0 | O8: =IFERROR(__xludf.DUMMYFUNCTION("IFERROR(SUM(FILTER($H:$H, $D:$D=$L8, TEXT($A:$A,""MMM YYYY"")=O$2)),0)"),0.0) -> 0
A9: =DATE(2026,2,22) -> 46075 | B9: Revant visit Palava - Biriyani | C9: Food and Drinks | D9: Delivery | E9: Credit Card | F9: Axis Bank CC | G9: Axis Bank CC | H9: 1242 | L9: Random Groceries | M9: 2000 | N9: =IFERROR(__xludf.DUMMYFUNCTION("IFERROR(SUM(FILTER($H:$H, $D:$D=$L9, TEXT($A:$A,""MMM YYYY"")=$N$2)),0)"),1091.28) -> 1091.28 | O9: =IFERROR(__xludf.DUMMYFUNCTION("IFERROR(SUM(FILTER($H:$H, $D:$D=$L9, TEXT($A:$A,""MMM YYYY"")=O$2)),0)"),1211.0) -> 1211
A10: =DATE(2026,2,22) -> 46075 | B10: Revant visit Palava - Misal | C10: Food and Drinks | D10: Delivery | E10: Credit Card | F10: Axis Bank CC | G10: Axis Bank CC | H10: 339 | L10: Total | M10: =SUM(M3:M9) -> 29354 | N10: =SUM(N3:N9) -> 2542.47 | O10: =SUM(O3:O9) -> 14252
A11: =DATE(2026,2,22) -> 46075 | B11: Blinkit Ketchup | C11: Household | D11: Fixed Groceries | E11: UPI/Bank Accounts | F11: State Bank of India (SBI) | G11: Paytm | H11: 233.5
A12: =DATE(2026,2,23) -> 46076 | B12: Zepto | C12: Cigarettes | E12: UPI/Bank Accounts | F12: State Bank of India (SBI) | G12: Paytm | H12: 390
A13: =DATE(2026,2,24) -> 46077 | B13: Futurezenith Insights - workshop | C13: Education | E13: UPI/Bank Accounts | F13: State Bank of India (SBI) | G13: Paytm | H13: 98
A14: =DATE(2026,2,25) -> 46078 | B14: Airtel Recharge | C14: Others | E14: UPI/Bank Accounts | F14: State Bank of India (SBI) | G14: Paytm | H14: 580.8
A15: =DATE(2026,2,26) -> 46079 | B15: IRCTC - Bhopal to Kalyan | C15: Trip | D15: Travelling | E15: UPI/Bank Accounts | F15: State Bank of India (SBI) | G15: Paytm | H15: 1888.6
A16: =DATE(2026,2,26) -> 46079 | B16: IRCTC - Haridwar to Bhopal | C16: Trip | D16: Travelling | E16: UPI/Bank Accounts | F16: State Bank of India (SBI) | G16: Paytm | H16: 1913.6
A17: =DATE(2026,2,28) -> 46081 | B17: iCloud Subscription | C17: Subscriptions | E17: UPI/Bank Accounts | F17: State Bank of India (SBI) | G17: Paytm | H17: 75
A18: =DATE(2026,2,28) -> 46081 | B18: Medicine - random | C18: Medical Spends | E18: UPI/Bank Accounts | F18: State Bank of India (SBI) | G18: Paytm | H18: 105
A19: =DATE(2026,2,28) -> 46081 | B19: Medicine - random | C19: Medical Spends | E19: UPI/Bank Accounts | F19: State Bank of India (SBI) | G19: Paytm | H19: 48
A20: =DATE(2026,2,28) -> 46081 | B20: Chai | C20: Food and Drinks | D20: Eating Out | E20: UPI/Bank Accounts | F20: State Bank of India (SBI) | G20: Paytm | H20: 10
A21: =DATE(2026,2,28) -> 46081 | B21: Milk paneer | C21: Household | D21: Fixed Groceries | E21: UPI/Bank Accounts | F21: State Bank of India (SBI) | G21: Paytm | H21: 99
A22: =DATE(2026,2,28) -> 46081 | B22: Medicine - random | C22: Medical Spends | E22: UPI/Bank Accounts | F22: State Bank of India (SBI) | G22: Paytm | H22: 239.36
A23: =DATE(2026,2,28) -> 46081 | B23: Zepto | C23: Household | D23: Random Groceries | E23: UPI/Bank Accounts | F23: State Bank of India (SBI) | G23: Paytm | H23: 211
A24: =DATE(2026,2,28) -> 46081 | B24: Blinkit | C24: Household | D24: Random Groceries | E24: UPI/Bank Accounts | F24: State Bank of India (SBI) | G24: Paytm | H24: 254
A25: =DATE(2026,2,28) -> 46081 | B25: Bike to Hospital | C25: Transport | D25: Auto/Cab | E25: UPI/Bank Accounts | F25: State Bank of India (SBI) | G25: Paytm | H25: 182
A26: =DATE(2026,2,28) -> 46081 | B26: ENT consultation fee | C26: Medical Spends | E26: UPI/Bank Accounts | F26: State Bank of India (SBI) | G26: Paytm | H26: 500
A27: =DATE(2026,2,28) -> 46081 | B27: Medicine - prescribed | C27: Medical Spends | E27: UPI/Bank Accounts | F27: State Bank of India (SBI) | G27: Paytm | H27: 1170
A28: =DATE(2026,2,28) -> 46081 | B28: Medicine - prescribed | C28: Medical Spends | E28: UPI/Bank Accounts | F28: State Bank of India (SBI) | G28: Paytm | H28: 208
A29: =DATE(2026,2,28) -> 46081 | B29: Cab to Home | C29: Transport | D29: Auto/Cab | E29: UPI/Bank Accounts | F29: State Bank of India (SBI) | G29: Paytm | H29: 208
A30: =DATE(2026,3,1) -> 46082 | B30: Youtube Premium Subscription | C30: Subscriptions | E30: UPI/Bank Accounts | F30: State Bank of India (SBI) | G30: Gpay | H30: 49.83
A31: =DATE(2026,3,1) -> 46082 | B31: Zepto | C31: Household | D31: Random Groceries | E31: UPI/Bank Accounts | F31: State Bank of India (SBI) | G31: Paytm | H31: 356
A32: =DATE(2026,3,1) -> 46082 | B32: Zepto | C32: Household | D32: Random Groceries | E32: UPI/Bank Accounts | F32: State Bank of India (SBI) | G32: Paytm | H32: 122
A33: =DATE(2026,3,1) -> 46082 | B33: Zepto | C33: Household | D33: Random Groceries | E33: UPI/Bank Accounts | F33: State Bank of India (SBI) | G33: Paytm | H33: 16
A34: =DATE(2026,3,1) -> 46082 | B34: Kissan connect | C34: Household | D34: Fixed Groceries | E34: UPI/Bank Accounts | F34: State Bank of India (SBI) | G34: Paytm | H34: 236
A35: =DATE(2026,3,2) -> 46083 | B35: RentoMojo | C35: Household | D35: Furniture Rent | E35: Credit Card | F35: Scapia | H35: 6308
A36: =DATE(2026,3,2) -> 46083 | B36: Water Purifier | C36: Others | E36: UPI/Bank Accounts | F36: State Bank of India (SBI) | G36: Paytm | H36: 1527
A37: =DATE(2026,3,3) -> 46084 | B37: Rapido to station | C37: Transport | D37: Auto/Cab | E37: UPI/Bank Accounts | F37: State Bank of India (SBI) | G37: Paytm | H37: 109
A38: =DATE(2026,3,3) -> 46084 | B38: Metro to DN Nagar | C38: Transport | D38: Metro | E38: UPI/Bank Accounts | F38: State Bank of India (SBI) | G38: Paytm | H38: 40
A39: =DATE(2026,3,3) -> 46084 | B39: Metro to Malad | C39: Transport | D39: Metro | E39: UPI/Bank Accounts | F39: State Bank of India (SBI) | G39: Paytm | H39: 20
A40: =DATE(2026,3,3) -> 46084 | B40: Roadside sandwich | C40: Food and Drinks | D40: Eating Out | E40: UPI/Bank Accounts | F40: State Bank of India (SBI) | G40: Paytm | H40: 70
...

Sheet Dropdown Lists
A1: Category Lists (from here the dropdowns are selected) - these are created automatically based on how user says it to the voice assistant | B1: Category (drop down list for column C) | C1: Subcategory (drop down list for column D) | E1: Account (drop down list for column E) | F1: Account - Subcategory (drop down list for column F)
B2: Food and Drinks | C2: Delivery | E2: Cash Payment
B3: Food and Drinks | C3: Eating Out | E3: UPI/Bank Accounts | F3: Axis Bank
B4: Cigarettes | E4: UPI/Bank Accounts | F4: State Bank of India (SBI)
B5: Recreation | E5: UPI/Bank Accounts | F5: Amazon Pay
B6: Transport | C6: Local | E6: UPI/Bank Accounts | F6: Groww Account
B7: Transport | C7: Metro | E7: Credit Card | F7: Axis Bank CC
B8: Transport | C8: Auto/Cab | E8: Credit Card | F8: ICICI
B9: Transport | C9: Petrol | E9: Credit Card | F9: Scapia
B10: Household | C10: House Rent | E10: Splitwise
B11: Household | C11: Fixed Groceries
B12: Household | C12: Random Groceries
B13: Household | C13: Maid Salary
B14: Household | C14: Electricity
B15: Household | C15: Furniture Rent
B16: Apparel
B17: Others
B18: Trip | C18: Travelling
B19: Trip | C19: Food
B20: Trip | C20: Accommodation
B21: Trip | C21: Household
B22: Trip | C22: Drinks and Cigarettes
B23: Trip | C23: Recreation
B24: Trip | C24: Miscellaneous
B25: Trip | C25: Gifts
B26: Subscriptions
B27: Education
B28: Medical Spends
B29: Investments | C29: Equity Stocks
B30: Investments | C30: SIP
B31: Investments | C31: Mutual Funds
B32: Investments | C32: NPS
B33: Investments | C33: Fixed Deposits
B34: Investments | C34: Brokerage
B35: Investments | C35: IPO locked/ Limit Buy

Sheet Colour Codes
B1: Description of Headlines
B2: Headlines - Highlight them
B3: string - from dropdown lists
B4: string - different rows inside sub-headline
B5: number, calculated and important (highlight)
B6: number/timestamp, formula based/ calculated field
B7: number, input field - important (highlight)
B8: number, input field
B9: headlines of dropdowns lists (used in apps script for dropdowns from C:G columns)
B10: dropdowns (fetched from dropdown lists)
B11: dropdown lists are present there
B12: MY FINAL PRODUCT

Sheet Actual Investments
C1: New Invested Amount
A2: Investment Summary | B2: Initial Invested Amount | C2: 46054 | D2: 46082 | E2: Total Investments
A3: Equity Stocks | B3: 213100 | C3: =IFERROR(SUMIFS(Kharche!$H:$H, Kharche!$A:$A, ">="&C$2, Kharche!$A:$A, "<="&EOMONTH(C$2,0),Kharche!$C:$C, "Investments", Kharche!$D:$D, $A3), 0) -> 0 | D3: =IFERROR(SUMIFS(Kharche!$H:$H, Kharche!$A:$A, ">="&D$2, Kharche!$A:$A, "<="&EOMONTH(D$2,0),Kharche!$C:$C, "Investments", Kharche!$D:$D, $A3), 0) -> 149368.25 | E3: =sum($B3:$D3) -> 362468.25
A4: SIP | B4: 0 | C4: =IFERROR(SUMIFS(Kharche!$H:$H, Kharche!$A:$A, ">="&C$2, Kharche!$A:$A, "<="&EOMONTH(C$2,0),Kharche!$C:$C, "Investments", Kharche!$D:$D, $A4), 0) -> 0 | D4: =IFERROR(SUMIFS(Kharche!$H:$H, Kharche!$A:$A, ">="&D$2, Kharche!$A:$A, "<="&EOMONTH(D$2,0),Kharche!$C:$C, "Investments", Kharche!$D:$D, $A4), 0) -> 0 | E4: =sum($B4:$D4) -> 0
A5: Mutual Funds | B5: 92995.16 | C5: =IFERROR(SUMIFS(Kharche!$H:$H, Kharche!$A:$A, ">="&C$2, Kharche!$A:$A, "<="&EOMONTH(C$2,0),Kharche!$C:$C, "Investments", Kharche!$D:$D, $A5), 0) -> 0 | D5: =IFERROR(SUMIFS(Kharche!$H:$H, Kharche!$A:$A, ">="&D$2, Kharche!$A:$A, "<="&EOMONTH(D$2,0),Kharche!$C:$C, "Investments", Kharche!$D:$D, $A5), 0) -> 55000 | E5: =sum($B5:$D5) -> 147995.16
A6: NPS | B6: 42840 | C6: =IFERROR(SUMIFS(Kharche!$H:$H, Kharche!$A:$A, ">="&C$2, Kharche!$A:$A, "<="&EOMONTH(C$2,0),Kharche!$C:$C, "Investments", Kharche!$D:$D, $A6), 0) -> 0 | D6: =IFERROR(SUMIFS(Kharche!$H:$H, Kharche!$A:$A, ">="&D$2, Kharche!$A:$A, "<="&EOMONTH(D$2,0),Kharche!$C:$C, "Investments", Kharche!$D:$D, $A6), 0) -> 0 | E6: =sum($B6:$D6) -> 42840
A7: Fixed Deposits | B7: 0 | C7: =IFERROR(SUMIFS(Kharche!$H:$H, Kharche!$A:$A, ">="&C$2, Kharche!$A:$A, "<="&EOMONTH(C$2,0),Kharche!$C:$C, "Investments", Kharche!$D:$D, $A7), 0) -> 0 | D7: =IFERROR(SUMIFS(Kharche!$H:$H, Kharche!$A:$A, ">="&D$2, Kharche!$A:$A, "<="&EOMONTH(D$2,0),Kharche!$C:$C, "Investments", Kharche!$D:$D, $A7), 0) -> 0 | E7: =sum($B7:$D7) -> 0
A8: IPO locked/ Limit Buy | B8: 0 | C8: =IFERROR(SUMIFS(Kharche!$H:$H, Kharche!$A:$A, ">="&C$2, Kharche!$A:$A, "<="&EOMONTH(C$2,0),Kharche!$C:$C, "Investments", Kharche!$D:$D, $A8), 0) -> 0 | D8: =IFERROR(SUMIFS(Kharche!$H:$H, Kharche!$A:$A, ">="&D$2, Kharche!$A:$A, "<="&EOMONTH(D$2,0),Kharche!$C:$C, "Investments", Kharche!$D:$D, $A8), 0) -> 29680 | E8: =sum($B8:$D8) -> 29680
A9: Brokerage | B9: 0 | C9: =IFERROR(SUMIFS(Kharche!$H:$H, Kharche!$A:$A, ">="&C$2, Kharche!$A:$A, "<="&EOMONTH(C$2,0),Kharche!$C:$C, "Investments", Kharche!$D:$D, $A9), 0) -> 0 | D9: =IFERROR(SUMIFS(Kharche!$H:$H, Kharche!$A:$A, ">="&D$2, Kharche!$A:$A, "<="&EOMONTH(D$2,0),Kharche!$C:$C, "Investments", Kharche!$D:$D, $A9), 0) -> 248.87 | E9: =sum($B9:$D9) -> 248.87
A10: Profit Booking - Equity Stocks | B10: 0 | C10: =IFERROR(SUMIFS(Kharche!$H:$H, Kharche!$A:$A, ">="&C$2, Kharche!$A:$A, "<="&EOMONTH(C$2,0),Kharche!$C:$C, "Investments", Kharche!$D:$D, $A10), 0) -> 0 | D10: =IFERROR(SUMIFS('AdhocSelf Transfer'!$D:$D, 'AdhocSelf Transfer'!$A:$A, ">="&D$2, 'AdhocSelf Transfer'!$A:$A, "<="&EOMONTH(D$2,0), 'AdhocSelf Transfer'!$B:$B, $A10), 0) -> 71.91 | E10: =sum($B10:$D10) -> 71.91
A11: Total Investment | B11: =sum(B3:B10) -> 348935.16 | C11: =sum(C3:C8) -> 0 | D11: =sum(D3:D8) -> 234048.25 | E11: =sum(E3:E8) -> 582983.41

Sheet Sheet8
A1: Credit Card | C1: Credit Card | D1: Scapia
A2: Household | B2: Fixed Groceries | C2: UPI | D2: State Bank of India (SBI)
A3: Electricity | C3: UPI | D3: State Bank of India (SBI)
A4: Food and Drinks | B4: Eating Out | C4: UPI | D4: State Bank of India (SBI)
A5: Household | B5: Fixed Groceries | C5: UPI | D5: State Bank of India (SBI)
A6: Cigarettes | C6: UPI | D6: State Bank of India (SBI)
A7: Food and Drinks | B7: Delivery | C7: Credit Card | D7: Axis Bank
A8: Food and Drinks | B8: Delivery | C8: Credit Card | D8: Axis Bank
A9: Household | B9: Fixed Groceries | C9: UPI | D9: State Bank of India (SBI)
A10: Cigarettes | C10: UPI | D10: State Bank of India (SBI)
A11: Education | B11: Education | C11: UPI | D11: State Bank of India (SBI)
A12: Others | B12: Input field (because others selected): Recharge | C12: UPI | D12: State Bank of India (SBI)
A13: Trip | B13: Travelling | C13: UPI | D13: State Bank of India (SBI)
A14: Trip | B14: Travelling | C14: UPI | D14: State Bank of India (SBI)
A15: Subscriptions | C15: UPI | D15: State Bank of India (SBI)
A16: Medical Spends | C16: UPI | D16: State Bank of India (SBI)
A17: Medical Spends | C17: UPI | D17: State Bank of India (SBI)
A18: Food and Drinks | B18: Eating Out | C18: UPI | D18: State Bank of India (SBI)
A19: Household | B19: Fixed Groceries | C19: UPI | D19: State Bank of India (SBI)
A20: Medical Spends | C20: UPI | D20: State Bank of India (SBI)
A21: Household | B21: Random Groceries | C21: UPI | D21: State Bank of India (SBI)
A22: Household | B22: Random Groceries | C22: UPI | D22: State Bank of India (SBI)
A23: Transport | B23: Auto/Cab | C23: UPI | D23: State Bank of India (SBI)
A24: Medical Spends | C24: UPI | D24: State Bank of India (SBI)
A25: Medical Spends | C25: UPI | D25: State Bank of India (SBI)
A26: Medical Spends | C26: UPI | D26: State Bank of India (SBI)
A27: Transport | B27: Auto/Cab | C27: UPI | D27: State Bank of India (SBI)
A28: Subscriptions | B28: Fixed Groceries | C28: UPI | D28: State Bank of India (SBI)
A29: Household | B29: Random Groceries | C29: UPI | D29: State Bank of India (SBI)
A30: Household | B30: Random Groceries | C30: UPI | D30: State Bank of India (SBI)
A31: Household | B31: Random Groceries | C31: UPI | D31: State Bank of India (SBI)
A32: Household | B32: Random Groceries | C32: UPI | D32: State Bank of India (SBI)
A33: Household | B33: Fixed Cost | C33: UPI | D33: State Bank of India (SBI)
A34: Transport | B34: Auto/Cab | C34: UPI | D34: State Bank of India (SBI)
A35: Transport | B35: Metro | C35: UPI | D35: State Bank of India (SBI)
A36: Transport | B36: Metro | C36: UPI | D36: State Bank of India (SBI)
A37: Food and Drinks | B37: Eating Out | C37: UPI | D37: State Bank of India (SBI)
A38: Cigarettes | C38: UPI | D38: State Bank of India (SBI)
A39: Transport | B39: Auto/Cab | C39: UPI | D39: State Bank of India (SBI)
A40: Household | B40: Maid Salary | C40: UPI | D40: State Bank of India (SBI)
...

Sheet New Investments Planner
A1: New investment i want to make | B1: 400000 | C1: 46082
A2: Fund Type | B2: Target Amount | C2: ="Actual Investmed Amount - "&TEXT(C1,"MMM YYYY") -> Actual Investmed Amount - Mar 2026
A3: Equity Stocks | B3: 100000 | C3: =IFERROR(SUMIFS(Kharche!$H:$H, Kharche!$A:$A, ">="&C$1, Kharche!$A:$A, "<="&EOMONTH(C$1,0),Kharche!$C:$C, 'Dropdown Lists'!B29, Kharche!$D:$D, $A3), 0) -> 149368.25
A4: SIP | B4: 20000 | C4: =IFERROR(SUMIFS(Kharche!$H:$H, Kharche!$A:$A, ">="&C$1, Kharche!$A:$A, "<="&EOMONTH(C$1,0),Kharche!$C:$C, 'Dropdown Lists'!B30, Kharche!$D:$D, $A4), 0) -> 0
A5: Mutual Funds | B5: 80000 | C5: =IFERROR(SUMIFS(Kharche!$H:$H, Kharche!$A:$A, ">="&C$1, Kharche!$A:$A, "<="&EOMONTH(C$1,0),Kharche!$C:$C, 'Dropdown Lists'!B31, Kharche!$D:$D, $A5), 0) -> 55000
A6: Fixed Deposits | B6: 100000 | C6: =IFERROR(SUMIFS(Kharche!$H:$H, Kharche!$A:$A, ">="&C$1, Kharche!$A:$A, "<="&EOMONTH(C$1,0),Kharche!$C:$C, 'Dropdown Lists'!B32, Kharche!$D:$D, $A6), 0) -> 0
A7: IPO locked/ Limit Buy | B7: 50000 | C7: =IFERROR(SUMIFS(Kharche!$H:$H, Kharche!$A:$A, ">="&C$1, Kharche!$A:$A, "<="&EOMONTH(C$1,0),Kharche!$C:$C, 'Dropdown Lists'!B33, Kharche!$D:$D, $A7), 0) -> 29680
A8: Brokerage | B8: 0 | C8: =IFERROR(SUMIFS(Kharche!$H:$H, Kharche!$A:$A, ">="&C$1, Kharche!$A:$A, "<="&EOMONTH(C$1,0),Kharche!$C:$C, 'Dropdown Lists'!B34, Kharche!$D:$D, $A8), 0) -> 248.87
A9: Total Investment | B9: =sum(B3:B8) -> 350000 | C9: =sum(C3:C7) -> 234048.25
A10: Remaining amount | B10: =B1-B9 -> 50000 | C10: =B1-C9 -> 165951.75

Sheet Credit Card Bills
A1: Date | B1: Paid From Account | C1: Credit Card | D1: Amount
A2: =date(2026,3,4) -> 46085 | B2: Axis Bank | C2: Axis Bank CC | D2: 2371.5

Sheet AdhocSelf Transfer
A1: Self Transfer, Refunds, Dividends
A2: Date | B2: From | C2: To | D2: Amount | E2: Buffer Amount
B3: Splitwise | C3: State Bank of India (SBI) | D3: 78014 | E3: 0.75
B4: State Bank of India (SBI) | C4: Axis Bank | D4: 50000 | E4: 0
A5: =DATE(2026,2,1) -> 46054 | B5: Dividend | C5: Axis Bank | D5: 41.25 | E5: 0
A6: =DATE(2026,3,1) -> 46082 | B6: Dividend | C6: Axis Bank | D6: 151.2 | E6: 0
A7: =DATE(2026,3,1) -> 46082 | B7: Refund | C7: State Bank of India (SBI) | D7: 19 | E7: 0
A8: =DATE(2026,3,2) -> 46083 | B8: Dividend | C8: Axis Bank | D8: 3.57 | E8: 0
A9: =DATE(2026,3,4) -> 46085 | B9: Axis Bank | C9: Groww Account | D9: 20000 | E9: 0
A10: =DATE(2026,3,4) -> 46085 | B10: State Bank of India (SBI) | C10: Amazon Pay | D10: 350 | E10: 0
A11: =DATE(2026,3,5) -> 46086 | B11: Axis Bank | C11: Groww Account | D11: 15000 | E11: 0
A12: =DATE(2026,3,5) -> 46086 | B12: Axis Bank | C12: Groww Account | D12: 5000 | E12: 0
A13: =DATE(2026,3,5) -> 46086 | B13: Axis Bank | C13: Groww Account | D13: 100 | E13: 0
A14: =DATE(2026,3,6) -> 46087 | B14: State Bank of India (SBI) | C14: Amazon Pay | D14: 350 | E14: 0
A15: =DATE(2026,3,7) -> 46088 | B15: State Bank of India (SBI) | C15: Amazon Pay | D15: 1000 | E15: 0
A16: =DATE(2026,3,8) -> 46089 | B16: Cashback | C16: Axis Bank CC | D16: 202 | E16: 0
A17: =DATE(2026,3,9) -> 46090 | B17: Axis Bank | C17: Groww Account | D17: 10000 | E17: 0
A18: =DATE(2026,3,9) -> 46090 | B18: Axis Bank | C18: Groww Account | D18: 10000 | E18: 0
A19: =DATE(2026,3,9) -> 46090 | B19: Axis Bank | C19: Groww Account | D19: 10000 | E19: 0
A20: =DATE(2026,3,9) -> 46090 | B20: Axis Bank | C20: Groww Account | D20: 15000 | E20: 0
A21: =DATE(2026,3,10) -> 46091 | B21: Dividend | C21: Axis Bank | D21: 62.4 | E21: 0
A22: =DATE(2026,3,10) -> 46091 | C22: Amazon Pay | D22: =59.37+24.44 -> 83.81 | E22: 0
A23: =DATE(2026,3,10) -> 46091 | C23: Cash Payment | D23: 3000 | E23: 0
A24: =DATE(2026,3,10) -> 46091 | B24: Profit Booking - Equity Stocks | C24: Groww Account | D24: 71.91 | E24: 0
A25: =DATE(2026,3,12) -> 46093 | B25: Cashback | C25: Axis Bank CC | D25: 52 | E25: 0
A26: =DATE(2026,3,15) -> 46096 | B26: Axis Bank | C26: State Bank of India (SBI) | D26: 20000 | E26: 0
A27: =DATE(2026,3,16) -> 46097 | B27: State Bank of India (SBI) | C27: Amazon Pay | D27: 144.53 | E27: 0
A28: =DATE(2026,3,16) -> 46097 | B28: Axis Bank | C28: Groww Account | D28: 10000 | E28: 0
A29: =DATE(2026,3,16) -> 46097 | B29: Axis Bank | C29: Groww Account | D29: 10000 | E29: 0
A30: =DATE(2026,3,17) -> 46098 | C30: State Bank of India (SBI) | D30: 3000 | E30: 0
A31: =DATE(2026,3,20) -> 46101 | C31: Groww Account | D31: 8550.49 | E31: 0
A32: =DATE(2026,3,21) -> 46102 | C32: Cash Payment | D32: 4500 | E32: 0
A33: =DATE(2026,3,24) -> 46105 | C33: Axis Bank | D33: 122.85 | E33: 0
A34: =DATE(2026,3,25) -> 46106 | C34: State Bank of India (SBI) | D34: 131 | E34: 0
A35: =DATE(2026,3,26) -> 46107 | B35: Axis Bank | C35: State Bank of India (SBI) | D35: 10000 | E35: 0
